<?xml version="1.0" encoding="utf-8"?>
<!-- =================================================================================== -->
<!-- |    This document was autogenerated by xacro from model.xacro                    | -->
<!-- |    EDITING THIS FILE BY HAND IS NOT RECOMMENDED                                 | -->
<!-- =================================================================================== -->
<robot name="porter" xmlns:xacro="http://www.ros.org/wiki/xacro">
  <!-- Material block -->
  <material name="blue">
    <color rgba="0 0 0.8 1"/>
  </material>
  <material name="white">
    <color rgba="1 1 1 1"/>
  </material>
  <material name="green">
    <color rgba="0 0.8 0 1"/>
  </material>
  <!-- Here actual model begins -->
  <link name="chasiss">
    <visual>
      <geometry>
        <box size="0.9 0.5 0.05"/>
      </geometry>
      <material name="blue"/>
    </visual>
    <collision>
      <geometry>
        <box size="0.9 0.5 0.05"/>
      </geometry>
    </collision>
    <inertial>
      <mass value="4"/>
      <inertia ixx="0.0841666666667" ixy="0.0" ixz="0.0" iyy="0.270833333333" iyz="0.0" izz="0.353333333333"/>
    </inertial>
  </link>
  <link name="right_actuated_wheel">
    <visual>
      <geometry>
        <cylinder length="0.03" radius="0.127"/>
      </geometry>
      <origin rpy="1.57075 0 0" xyz="0 0 0"/>
      <material name="green"/>
    </visual>
    <collision>
      <geometry>
        <cylinder length="0.03" radius="0.127"/>
      </geometry>
    </collision>
    <inertial>
      <mass value="1"/>
      <inertia ixx="0.00410725" ixy="0.0" ixz="0.0" iyy="0.0080645" iyz="0.0" izz="0.00410725"/>
    </inertial>
  </link>
  <joint name="chasiss_to_right_actuated_wheel" type="continuous">
    <parent link="chasiss"/>
    <child link="right_actuated_wheel"/>
    <axis xyz="0 1 0"/>
    <origin xyz="0.4 -0.265 0"/>
  </joint>
  <link name="left_actuated_wheel">
    <visual>
      <geometry>
        <cylinder length="0.03" radius="0.127"/>
      </geometry>
      <origin rpy="1.57075 0 0" xyz="0 0 0"/>
      <material name="green"/>
    </visual>
    <collision>
      <geometry>
        <cylinder length="0.03" radius="0.127"/>
      </geometry>
    </collision>
    <inertial>
      <mass value="1"/>
      <inertia ixx="0.00410725" ixy="0.0" ixz="0.0" iyy="0.0080645" iyz="0.0" izz="0.00410725"/>
    </inertial>
  </link>
  <joint name="chasiss_to_left_actuated_wheel" type="continuous">
    <parent link="chasiss"/>
    <child link="left_actuated_wheel"/>
    <axis xyz="0 1 0"/>
    <origin xyz="0.4 0.265 0"/>
  </joint>
  <link name="right_free_wheel">
    <visual>
      <geometry>
        <cylinder length="0.03" radius="0.127"/>
      </geometry>
      <origin rpy="1.57075 0 0" xyz="0 0 0"/>
      <material name="white"/>
    </visual>
    <collision>
      <geometry>
        <cylinder length="0.03" radius="0.127"/>
      </geometry>
    </collision>
    <inertial>
      <mass value="1"/>
      <inertia ixx="0.00410725" ixy="0.0" ixz="0.0" iyy="0.0080645" iyz="0.0" izz="0.00410725"/>
    </inertial>
  </link>
  <joint name="chasiss_to_right_free_wheel" type="continuous">
    <parent link="chasiss"/>
    <child link="right_free_wheel"/>
    <axis xyz="0 1 0"/>
    <origin xyz="-0.4 -0.265 0"/>
  </joint>
  <link name="left_free_wheel">
    <visual>
      <geometry>
        <cylinder length="0.03" radius="0.127"/>
      </geometry>
      <origin rpy="1.57075 0 0" xyz="0 0 0"/>
      <material name="white"/>
    </visual>
    <collision>
      <geometry>
        <cylinder length="0.03" radius="0.127"/>
      </geometry>
    </collision>
    <inertial>
      <mass value="1"/>
      <inertia ixx="0.00410725" ixy="0.0" ixz="0.0" iyy="0.0080645" iyz="0.0" izz="0.00410725"/>
    </inertial>
  </link>
  <joint name="chasiss_to_left_free_wheel" type="continuous">
    <parent link="chasiss"/>
    <child link="left_free_wheel"/>
    <axis xyz="0 1 0"/>
    <origin xyz="-0.4 0.265 0"/>
  </joint>
</robot>

