<?xml version="1.0" encoding="utf-8"?>
<!-- =================================================================================== -->
<!-- |    This document was autogenerated by xacro from model.xacro                    | -->
<!-- |    EDITING THIS FILE BY HAND IS NOT RECOMMENDED                                 | -->
<!-- =================================================================================== -->
<robot name="porter" xmlns:xacro="http://www.ros.org/wiki/xacro">
  <!-- Parameters of the lidar -->
  <!-- Material block -->
  <material name="blue">
    <color rgba="0 0 0.8 1"/>
  </material>
  <material name="white">
    <color rgba="1 1 1 1"/>
  </material>
  <material name="green">
    <color rgba="0 0.8 0 1"/>
  </material>
  <!-- Some useful macroses -->
  <!-- End of macroses -->
  <gazebo reference="chasiss">
    <mu1 value="200.0"/>
    <mu2 value="100.0"/>
    <kp value="2147483647.0"/>
    <kd value="1.0"/>
    <material>Gazebo/White</material>
  </gazebo>
  <gazebo>
    <plugin filename="libgazebo_ros_control.so" name="gazebo_ros_control">
      <robotNamespace>/</robotNamespace>
    </plugin>
    <plugin filename="libgazebo_ros_diff_drive.so" name="differential_drive_controller">
      <commandTopic>cmd_vel</commandTopic>
      <odometryTopic>odom</odometryTopic>
      <odometryFrame>odom</odometryFrame>
      <robotBaseFrame>chasiss</robotBaseFrame>
      <publishWheelTF>true</publishWheelTF>
      <publishWheelJointState>true</publishWheelJointState>
      <legacyMode>false</legacyMode>
      <wheelSeparation>0.83</wheelSeparation>
      <wheelDiameter>0.254</wheelDiameter>
      <wheelAcceleration>100</wheelAcceleration>
      <wheelTorque>100</wheelTorque>
      <updateRate>50</updateRate>
      <leftJoint>chasiss_to_left_actuated_wheel</leftJoint>
      <rightJoint>chasiss_to_right_actuated_wheel</rightJoint>
      <publishTf>1</publishTf>
    </plugin>
  </gazebo>
  <!-- Camera -->
  <link name="camera_main">
    <collision>
      <origin rpy="0 0 0" xyz="0 0 0"/>
      <geometry>
        <box size="0.05 0.05 0.05"/>
      </geometry>
    </collision>
    <visual>
      <origin rpy="0 0 0" xyz="0 0 0"/>
      <geometry>
        <box size="0.05 0.05 0.05"/>
      </geometry>
      <material name="red"/>
    </visual>
    <inertial>
      <mass value="1e-5"/>
      <origin rpy="0 0 0" xyz="0 0 0"/>
      <inertia ixx="1e-6" ixy="0" ixz="0" iyy="1e-6" iyz="0" izz="1e-6"/>
    </inertial>
  </link>
  <joint name="camera_joint" type="fixed">
    <axis xyz="0 0 0"/>
    <origin rpy="0 0 0" xyz="0.325 -0.1 0.275"/>
    <parent link="control_box"/>
    <child link="camera_main"/>
  </joint>
  <gazebo reference="camera_main">
    <sensor name="camera_main" type="camera">
      <update_rate>30.0</update_rate>
      <camera name="head">
        <horizontal_fov>1.3962634</horizontal_fov>
        <image>
          <width>640</width>
          <height>480</height>
          <format>R8G8B8</format>
        </image>
        <clip>
          <near>0.02</near>
          <far>300</far>
        </clip>
        <noise>
          <type>gaussian</type>
          <!-- Noise is sampled independently per pixel on each frame.
			That pixel's noise value is added to each of its color
			channels, which at that point lie in the range [0,1]. -->
          <mean>0.0</mean>
          <stddev>0.007</stddev>
        </noise>
      </camera>
      <plugin filename="libgazebo_ros_camera.so" name="camera_controller">
        <alwaysOn>true</alwaysOn>
        <updateRate>0.0</updateRate>
        <cameraName>porter/camera_main</cameraName>
        <imageTopicName>image_raw</imageTopicName>
        <cameraInfoTopicName>camera_info</cameraInfoTopicName>
        <frameName>camera_main</frameName>
        <hackBaseline>0.07</hackBaseline>
        <distortionK1>0.0</distortionK1>
        <distortionK2>0.0</distortionK2>
        <distortionK3>0.0</distortionK3>
        <distortionT1>0.0</distortionT1>
        <distortionT2>0.0</distortionT2>
      </plugin>
    </sensor>
  </gazebo>
  <!-- <xacro:macro name="OS1-64" params=" name:=  hz:=10 lasers:=64 samples:=512 min_range:=0.9 max_range:=75.0 noise:=0.008 min_angle:=-${M_PI} max_angle:=${M_PI}"> -->
  <joint name="mount_joint" type="fixed">
    <origin rpy="0 0 0" xyz="0.325 0.1 0.2865"/>
    <parent link="control_box"/>
    <child link="os1_sensor"/>
  </joint>
  <link name="os1_sensor">
    <inertial>
      <mass value="0.33"/>
      <origin rpy="0 0 0" xyz="0 0 0.0365"/>
      <inertia ixx="0.000241148" ixy="0" ixz="0" iyy="0.000241148" iyz="0" izz="0.000264"/>
    </inertial>
    <collision name="base_collision">
      <origin rpy="0 0 0" xyz="0 0 0.0365"/>
      <geometry>
        <cylinder length="0.073" radius="0.04"/>
      </geometry>
    </collision>
    <visual name="base_visual">
      <origin rpy="0 0 1.5707" xyz="0 0 0.0"/>
      <geometry>
        <mesh filename="package://porter_robot_model/meshes/os1_64.dae"/>
        <!-- <cylinder length="0.073" radius="0.04" /> -->
      </geometry>
    </visual>
  </link>
  <link name="os1_imu"/>
  <link name="os1_lidar"/>
  <joint name="imu_link_joint" type="fixed">
    <parent link="os1_sensor"/>
    <child link="os1_imu"/>
    <origin rpy="0 0 0" xyz="0.006253 -0.011775 0.007645"/>
  </joint>
  <gazebo reference="os1_imu">
    </gazebo>
  <joint name="lidar_link_joint" type="fixed">
    <parent link="os1_sensor"/>
    <child link="os1_lidar"/>
    <origin rpy="0 0 0" xyz="0.0 0.0 0.03618"/>
  </joint>
  <!-- Gazebo requires the ouster_gazebo_plugins package -->
  <gazebo reference="os1_sensor">
    <sensor name="os1_sensor" type="ray">
      <pose>0 0 0 0 0 0</pose>
      <visualize>false</visualize>
      <update_rate>10</update_rate>
      <ray>
        <scan>
          <horizontal>
            <samples>512</samples>
            <resolution>1</resolution>
            <min_angle>-3.14159265359</min_angle>
            <max_angle>3.14159265359</max_angle>
          </horizontal>
          <vertical>
            <samples>64</samples>
            <resolution>1</resolution>
            <min_angle>-0.261799387799</min_angle>
            <max_angle>0.261799387799</max_angle>
          </vertical>
        </scan>
        <range>
          <min>0.9</min>
          <max>75.0</max>
          <resolution>0.03</resolution>
        </range>
      </ray>
      <plugin filename="libgazebo_ros_laser.so" name="gazebo_ros_laser_controller">
        <topicName>/os1_cloud_node/points</topicName>
        <frameName>os1_lidar</frameName>
        <min_range>0.9</min_range>
        <max_range>75.0</max_range>
        <gaussianNoise>0.008</gaussianNoise>
      </plugin>
    </sensor>
  </gazebo>
  <!-- IMU -->
  <gazebo>
    <plugin filename="libhector_gazebo_ros_imu.so" name="imu_controller">
      <robotNamespace>/</robotNamespace>
      <updateRate>100.0</updateRate>
      <bodyName>os1_imu</bodyName>
      <topicName>/os1_cloud_node/imu</topicName>
      <accelDrift>0.005 0.005 0.005</accelDrift>
      <accelGaussianNoise>0.005 0.005 0.005</accelGaussianNoise>
      <rateDrift>0.005 0.005 0.005 </rateDrift>
      <rateGaussianNoise>0.005 0.005 0.005 </rateGaussianNoise>
      <headingDrift>0.005</headingDrift>
      <headingGaussianNoise>0.005</headingGaussianNoise>
    </plugin>
  </gazebo>
  <!-- Here actual model begins -->
  <link name="chasiss">
    <visual>
      <geometry>
        <box size="0.7 0.7 0.045"/>
      </geometry>
      <origin rpy="0 0 0" xyz="0 0 0"/>
      <material name="blue"/>
    </visual>
    <collision>
      <geometry>
        <box size="0.7 0.7 0.045"/>
      </geometry>
    </collision>
    <inertial>
      <mass value="15"/>
      <inertia ixx="0.61503125" ixy="0.0" ixz="0.0" iyy="0.61503125" iyz="0.0" izz="1.225"/>
    </inertial>
  </link>
  <link name="control_box">
    <visual>
      <geometry>
        <box size="0.7 0.7 0.5"/>
      </geometry>
      <origin rpy="0 0 0" xyz="0 0 0"/>
      <material name="blue"/>
    </visual>
    <collision>
      <geometry>
        <box size="0.7 0.7 0.5"/>
      </geometry>
    </collision>
    <inertial>
      <mass value="3"/>
      <inertia ixx="0.185" ixy="0.0" ixz="0.0" iyy="0.185" iyz="0.0" izz="0.245"/>
    </inertial>
  </link>
  <joint name="chasiss_to_control_box" type="fixed">
    <parent link="chasiss"/>
    <child link="control_box"/>
    <origin rpy="0 0 0" xyz="0.0 0.0 0.2725"/>
  </joint>
  <link name="right_actuated_wheel">
    <visual>
      <geometry>
        <cylinder length="0.048" radius="0.127"/>
      </geometry>
      <origin rpy="1.57075 0 0" xyz="0 0 0"/>
      <material name="green"/>
    </visual>
    <collision>
      <geometry>
        <cylinder length="0.048" radius="0.127"/>
      </geometry>
      <origin rpy="1.57075 0 0" xyz="0 0 0"/>
    </collision>
    <inertial>
      <mass value="3"/>
      <inertia ixx="0.01267275" ixy="0.0" ixz="0.0" iyy="0.0241935" iyz="0.0" izz="0.01267275"/>
    </inertial>
  </link>
  <joint name="chasiss_to_right_actuated_wheel" type="continuous">
    <parent link="chasiss"/>
    <child link="right_actuated_wheel"/>
    <axis xyz="0 1 0"/>
    <origin xyz="0.285 -0.415 0"/>
  </joint>
  <transmission name="right_actuated_wheel_trans">
    <type>transmission_interface/SimpleTransmission</type>
    <actuator name="right_actuated_wheel_motor">
      <mechanicalReduction>1</mechanicalReduction>
    </actuator>
    <joint name="chasiss_to_right_actuated_wheel">
      <hardwareInterface>hardware_interface/VelocityJointInterface</hardwareInterface>
    </joint>
  </transmission>
  <gazebo reference="right_actuated_wheel">
    <mu1 value="200.0"/>
    <mu2 value="200.0"/>
    <material>Gazebo/Grey</material>
  </gazebo>
  <link name="left_actuated_wheel">
    <visual>
      <geometry>
        <cylinder length="0.048" radius="0.127"/>
      </geometry>
      <origin rpy="1.57075 0 0" xyz="0 0 0"/>
      <material name="green"/>
    </visual>
    <collision>
      <geometry>
        <cylinder length="0.048" radius="0.127"/>
      </geometry>
      <origin rpy="1.57075 0 0" xyz="0 0 0"/>
    </collision>
    <inertial>
      <mass value="3"/>
      <inertia ixx="0.01267275" ixy="0.0" ixz="0.0" iyy="0.0241935" iyz="0.0" izz="0.01267275"/>
    </inertial>
  </link>
  <joint name="chasiss_to_left_actuated_wheel" type="continuous">
    <parent link="chasiss"/>
    <child link="left_actuated_wheel"/>
    <axis xyz="0 1 0"/>
    <origin xyz="0.285 0.415 0"/>
  </joint>
  <transmission name="left_actuated_wheel_trans">
    <type>transmission_interface/SimpleTransmission</type>
    <actuator name="left_actuated_wheel_motor">
      <mechanicalReduction>1</mechanicalReduction>
    </actuator>
    <joint name="chasiss_to_left_actuated_wheel">
      <hardwareInterface>hardware_interface/VelocityJointInterface</hardwareInterface>
    </joint>
  </transmission>
  <gazebo reference="left_actuated_wheel">
    <mu1 value="200.0"/>
    <mu2 value="200.0"/>
    <material>Gazebo/Grey</material>
  </gazebo>
  <link name="right_free_wheel">
    <visual>
      <geometry>
        <sphere radius="0.05"/>
      </geometry>
      <origin rpy="1.57075 0 0" xyz="0 0 0"/>
      <material name="white"/>
    </visual>
    <collision>
      <geometry>
        <sphere radius="0.05"/>
      </geometry>
      <origin rpy="1.57075 0 0" xyz="0 0 0"/>
    </collision>
    <inertial>
      <mass value="1"/>
      <inertia ixx="0.001" ixy="0.0" ixz="0.0" iyy="0.001" iyz="0.0" izz="0.001"/>
    </inertial>
  </link>
  <joint name="chasiss_to_right_free_wheel" type="fixed">
    <parent link="chasiss"/>
    <child link="right_free_wheel"/>
    <origin xyz="-0.4 -0.335 -0.077"/>
  </joint>
  <gazebo reference="right_free_wheel">
    <mu1 value="0"/>
    <mu2 value="0"/>
    <material>Gazebo/Grey</material>
  </gazebo>
  <link name="left_free_wheel">
    <visual>
      <geometry>
        <sphere radius="0.05"/>
      </geometry>
      <origin rpy="1.57075 0 0" xyz="0 0 0"/>
      <material name="white"/>
    </visual>
    <collision>
      <geometry>
        <sphere radius="0.05"/>
      </geometry>
      <origin rpy="1.57075 0 0" xyz="0 0 0"/>
    </collision>
    <inertial>
      <mass value="1"/>
      <inertia ixx="0.001" ixy="0.0" ixz="0.0" iyy="0.001" iyz="0.0" izz="0.001"/>
    </inertial>
  </link>
  <joint name="chasiss_to_left_free_wheel" type="fixed">
    <parent link="chasiss"/>
    <child link="left_free_wheel"/>
    <origin xyz="-0.4 0.335 -0.077"/>
  </joint>
  <gazebo reference="left_free_wheel">
    <mu1 value="0"/>
    <mu2 value="0"/>
    <material>Gazebo/Grey</material>
  </gazebo>
</robot>

